<?xml version="1.0" ?>
<!-- =================================================================================== -->
<!-- |    This document was autogenerated by xacro from el_a3_description/urdf/el_a3.urdf.xacro              | -->
<!-- |    EDITING THIS FILE BY HAND IS NOT RECOMMENDED                                 | -->
<!-- =================================================================================== -->
<!-- EL-A3 6-DOF Robot Arm URDF with ros2_control support -->
<!-- Updated from EDULITE-A3 model -->
<robot name="EL-A3">
  <!-- Materials -->
  <material name="orange">
    <color rgba="0.972549 0.529412 0.00392157 1"/>
  </material>
  <material name="dark_brown">
    <color rgba="0.301961 0.290196 0.262745 1"/>
  </material>

  <!-- Base link (world) -->
  <link name="base_link"/>

  <joint name="base_to_l1" type="fixed">
    <parent link="base_link"/>
    <child link="l1_urdf_urdf_asm"/>
    <origin xyz="0 0 0" rpy="0 0 0"/>
  </joint>

  <!-- Link l1_urdf_urdf_asm (Base) -->
  <link name="l1_urdf_urdf_asm">
    <inertial>
      <origin xyz="4.66057e-08 7.85527e-05 0.0336468" rpy="0 0 0"/>
      <mass value="0.498832"/>
      <inertia ixx="0.000371872" ixy="-1.33362e-08" ixz="5.96807e-10"
               iyy="0.000365137" iyz="-1.36721e-06" izz="0.000388475"/>
    </inertial>
    <visual>
      <origin xyz="-0.000643355 0 0.059" rpy="0 0 0"/>
      <geometry>
        <mesh filename="package://el_a3_description/meshes/l1.stl"/>
      </geometry>
      <material name="dark_brown"/>
    </visual>
    <collision>
      <origin xyz="-0.000643355 0 0.059" rpy="0 0 0"/>
      <geometry>
        <mesh filename="package://el_a3_description/meshes/l1.stl"/>
      </geometry>
    </collision>
  </link>

  <!-- Link l1_link_urdf_asm -->
  <link name="l1_link_urdf_asm">
    <inertial>
      <origin xyz="-0.00232762 -0.00161986 0.0421389" rpy="0 0 0"/>
      <mass value="0.105244"/>
      <inertia ixx="0.000163151" ixy="-3.25924e-06" ixz="1.01303e-05"
               iyy="9.80821e-05" iyz="1.04567e-05" izz="0.000118753"/>
    </inertial>
    <visual>
      <origin xyz="-0.000642857 0 0.001" rpy="3.14159 0 0"/>
      <geometry>
        <mesh filename="package://el_a3_description/meshes/l2.stl"/>
      </geometry>
      <material name="orange"/>
    </visual>
    <collision>
      <origin xyz="-0.000642857 0 0.001" rpy="3.14159 0 0"/>
      <geometry>
        <mesh filename="package://el_a3_description/meshes/l2.stl"/>
      </geometry>
    </collision>
  </link>

  <!-- Link l2_l3_urdf_asm -->
  <link name="l2_l3_urdf_asm">
    <inertial>
      <origin xyz="0.0949957 1.32911e-06 0.000626283" rpy="0 0 0"/>
      <mass value="0.836196"/>
      <inertia ixx="0.000419405" ixy="-4.27021e-07" ixz="-4.05336e-10"
               iyy="0.00708317" iyz="2.8291e-09" izz="0.00707892"/>
    </inertial>
    <visual>
      <origin xyz="0.009 -0.07 0" rpy="-1.5708 0 0"/>
      <geometry>
        <mesh filename="package://el_a3_description/meshes/l3.stl"/>
      </geometry>
      <material name="dark_brown"/>
    </visual>
    <collision>
      <origin xyz="0.009 -0.07 0" rpy="-1.5708 0 0"/>
      <geometry>
        <mesh filename="package://el_a3_description/meshes/l3.stl"/>
      </geometry>
    </collision>
  </link>

  <!-- Link l3_lnik_urdf_asm -->
  <link name="l3_lnik_urdf_asm">
    <inertial>
      <origin xyz="-0.0743466 -0.0535452 -0.00326782" rpy="0 0 0"/>
      <mass value="0.262025"/>
      <inertia ixx="0.000333463" ixy="-0.000182996" ixz="-9.89508e-06"
               iyy="0.00130159" iyz="1.18614e-05" izz="0.00133147"/>
    </inertial>
    <visual>
      <origin xyz="-0.181 -0.07 0" rpy="-1.5708 0 0"/>
      <geometry>
        <mesh filename="package://el_a3_description/meshes/l4.stl"/>
      </geometry>
      <material name="orange"/>
    </visual>
    <collision>
      <origin xyz="-0.181 -0.07 0" rpy="-1.5708 0 0"/>
      <geometry>
        <mesh filename="package://el_a3_description/meshes/l4.stl"/>
      </geometry>
    </collision>
  </link>

  <!-- Link l4_l5_urdf_asm -->
  <link name="l4_l5_urdf_asm">
    <inertial>
      <origin xyz="-0.0242818 -0.0298393 0.000368105" rpy="0 0 0"/>
      <mass value="0.55715"/>
      <inertia ixx="0.0006785" ixy="-0.000401622" ixz="-5.0507e-06"
               iyy="0.000503952" iyz="-6.21816e-06" izz="0.000993465"/>
    </inertial>
    <visual>
      <origin xyz="0.004 0.134 0" rpy="1.5708 0 0"/>
      <geometry>
        <mesh filename="package://el_a3_description/meshes/l5.stl"/>
      </geometry>
      <material name="dark_brown"/>
    </visual>
    <collision>
      <origin xyz="0.004 0.134 0" rpy="1.5708 0 0"/>
      <geometry>
        <mesh filename="package://el_a3_description/meshes/l5.stl"/>
      </geometry>
    </collision>
  </link>

  <!-- Link part_9 -->
  <link name="part_9">
    <inertial>
      <origin xyz="0.00527533 0 -0.0216678" rpy="0 0 0"/>
      <mass value="0.0392349"/>
      <inertia ixx="1.45554e-05" ixy="0" ixz="4.08768e-06"
               iyy="1.4787e-05" iyz="0" izz="6.36147e-06"/>
    </inertial>
    <visual>
      <origin xyz="0.0532 0 0.173" rpy="3.14159 0 0"/>
      <geometry>
        <mesh filename="package://el_a3_description/meshes/l6.stl"/>
      </geometry>
      <material name="orange"/>
    </visual>
    <collision>
      <origin xyz="0.0532 0 0.173" rpy="3.14159 0 0"/>
      <geometry>
        <mesh filename="package://el_a3_description/meshes/l6.stl"/>
      </geometry>
    </collision>
  </link>

  <!-- Link l5_l6_urdf_asm (End Effector) -->
  <link name="l5_l6_urdf_asm">
    <inertial>
      <origin xyz="8.14367e-06 8.87434e-05 0.0699256" rpy="0 0 0"/>
      <mass value="0.657292"/>
      <inertia ixx="0.00132624" ixy="1.41465e-05" ixz="9.49712e-08"
               iyy="0.00177268" iyz="-7.87717e-06" izz="0.000610685"/>
    </inertial>
    <!-- Part el05_l6 -->
    <visual>
      <origin xyz="0 0 -0.0755" rpy="3.14159 0 0"/>
      <geometry>
        <mesh filename="package://el_a3_description/meshes/el05_l6.stl"/>
      </geometry>
      <material name="dark_brown"/>
    </visual>
    <collision>
      <origin xyz="0 0 -0.0755" rpy="3.14159 0 0"/>
      <geometry>
        <mesh filename="package://el_a3_description/meshes/el05_l6.stl"/>
      </geometry>
    </collision>
    <!-- Part jaw -->
    <visual>
      <origin xyz="0 0 -0.0755" rpy="3.14159 0 0"/>
      <geometry>
        <mesh filename="package://el_a3_description/meshes/jaw.stl"/>
      </geometry>
      <material name="orange"/>
    </visual>
    <collision>
      <origin xyz="0 0 -0.0755" rpy="3.14159 0 0"/>
      <geometry>
        <mesh filename="package://el_a3_description/meshes/jaw.stl"/>
      </geometry>
    </collision>
  </link>

  <!-- End Effector link -->
  <link name="end_effector"/>

  <!-- Joints -->
  <!-- Joint L1 (RS00 Motor 1) -->
  <joint name="L1_joint" type="revolute">
    <origin xyz="0 0 0.06" rpy="3.14159 0 0"/>
    <parent link="l1_urdf_urdf_asm"/>
    <child link="l1_link_urdf_asm"/>
    <axis xyz="0 0 -1"/>
    <limit effort="14" velocity="33" lower="-2.79253" upper="2.79253"/>
    <dynamics damping="0.1" friction="0.1"/>
  </joint>

  <!-- Joint L2 (RS00 Motor 2) -->
  <joint name="L2_joint" type="revolute">
    <origin xyz="-0.00964286 0 -0.069" rpy="-1.5708 0 0"/>
    <parent link="l1_link_urdf_asm"/>
    <child link="l2_l3_urdf_asm"/>
    <axis xyz="0 0 1"/>
    <limit effort="14" velocity="33" lower="0" upper="3.66519"/>
    <dynamics damping="0.1" friction="0.1"/>
  </joint>

  <!-- Joint L3 (RS00 Motor 3) -->
  <joint name="L3_joint" type="revolute">
    <origin xyz="0.19 0 0" rpy="0 0 0"/>
    <parent link="l2_l3_urdf_asm"/>
    <child link="l3_lnik_urdf_asm"/>
    <axis xyz="0 0 1"/>
    <limit effort="14" velocity="33" lower="-4.01426" upper="0"/>
    <dynamics damping="0.1" friction="0.1"/>
  </joint>

  <!-- Joint L4 (EL05 Motor 4) -->
  <joint name="L4_joint" type="revolute">
    <origin xyz="-0.185 0.064 0" rpy="-3.14159 0 0"/>
    <parent link="l3_lnik_urdf_asm"/>
    <child link="l4_l5_urdf_asm"/>
    <axis xyz="0 0 -1"/>
    <limit effort="6.0" velocity="50" lower="-1.0472" upper="1.5708"/>
    <dynamics damping="0.05" friction="0.05"/>
  </joint>

  <!-- Joint L5 (EL05 Motor 5) -->
  <joint name="L5_joint" type="revolute">
    <origin xyz="-0.0492 -0.038 0" rpy="-1.5708 0 0"/>
    <parent link="l4_l5_urdf_asm"/>
    <child link="part_9"/>
    <axis xyz="0 0 1"/>
    <limit effort="6.0" velocity="50" lower="-1.5708" upper="1.5708"/>
    <dynamics damping="0.05" friction="0.05"/>
  </joint>

  <!-- Joint L6 (EL05 Motor 6) -->
  <joint name="L6_joint" type="revolute">
    <origin xyz="0.00685 0 0.039" rpy="-1.5708 0 -1.5708"/>
    <parent link="part_9"/>
    <child link="l5_l6_urdf_asm"/>
    <axis xyz="0 0 1"/>
    <limit effort="6.0" velocity="50" lower="-1.5708" upper="1.5708"/>
    <dynamics damping="0.05" friction="0.05"/>
  </joint>

  <!-- End Effector joint (fixed to last arm link, defines TCP for MoveIt planning) -->
  <joint name="end_effector_joint" type="fixed">
    <origin xyz="0 0 -0.074" rpy="0 0 0"/>
    <parent link="l5_l6_urdf_asm"/>
    <child link="end_effector"/>
  </joint>

  <!-- Joint L7 (EL05 Motor 7 - Gripper, separate kinematic branch) -->
  <joint name="L7_joint" type="revolute">
    <origin xyz="0 0 -0.074" rpy="0 0 0"/>
    <parent link="l5_l6_urdf_asm"/>
    <child link="gripper_link"/>
    <axis xyz="0 0 1"/>
    <limit effort="6.0" velocity="50" lower="-1.5708" upper="1.5708"/>
    <dynamics damping="0.05" friction="0.05"/>
  </joint>

  <link name="gripper_link">
    <inertial>
      <mass value="0.05"/>
      <origin xyz="0 0 0"/>
      <inertia ixx="0.0001" ixy="0" ixz="0" iyy="0.0001" iyz="0" izz="0.0001"/>
    </inertial>
  </link>

  <!-- ros2_control (mock hardware for visualization) -->
  <ros2_control name="RsA3System" type="system">
    <hardware>
      <plugin>mock_components/GenericSystem</plugin>
      <param name="mock_sensor_commands">false</param>
    </hardware>

    <joint name="L1_joint">
      <param name="motor_id">1</param>
      <param name="motor_type">RS00</param>
      <param name="position_offset">0.0</param>
      <param name="direction">-1.0</param>
      <command_interface name="position">
        <param name="min">-2.79253</param>
        <param name="max">2.79253</param>
      </command_interface>
      <command_interface name="velocity">
        <param name="min">-33.0</param>
        <param name="max">33.0</param>
      </command_interface>
      <command_interface name="effort">
        <param name="min">-14.0</param>
        <param name="max">14.0</param>
      </command_interface>
      <state_interface name="position"/>
      <state_interface name="velocity"/>
      <state_interface name="effort"/>
    </joint>

    <joint name="L2_joint">
      <param name="motor_id">2</param>
      <param name="motor_type">RS00</param>
      <param name="position_offset">0.0</param>
      <param name="direction">1.0</param>
      <command_interface name="position">
        <param name="min">0</param>
        <param name="max">3.66519</param>
      </command_interface>
      <command_interface name="velocity">
        <param name="min">-33.0</param>
        <param name="max">33.0</param>
      </command_interface>
      <command_interface name="effort">
        <param name="min">-14.0</param>
        <param name="max">14.0</param>
      </command_interface>
      <state_interface name="position">
        <param name="initial_value">0.785</param>
      </state_interface>
      <state_interface name="velocity"/>
      <state_interface name="effort"/>
    </joint>

    <joint name="L3_joint">
      <param name="motor_id">3</param>
      <param name="motor_type">RS00</param>
      <param name="position_offset">0.0</param>
      <param name="direction">-1.0</param>
      <command_interface name="position">
        <param name="min">-4.01426</param>
        <param name="max">0</param>
      </command_interface>
      <command_interface name="velocity">
        <param name="min">-33.0</param>
        <param name="max">33.0</param>
      </command_interface>
      <command_interface name="effort">
        <param name="min">-14.0</param>
        <param name="max">14.0</param>
      </command_interface>
      <state_interface name="position">
        <param name="initial_value">-0.785</param>
      </state_interface>
      <state_interface name="velocity"/>
      <state_interface name="effort"/>
    </joint>

    <joint name="L4_joint">
      <param name="motor_id">4</param>
      <param name="motor_type">EL05</param>
      <param name="position_offset">0.0</param>
      <param name="direction">1.0</param>
      <param name="kp">100.0</param>
      <param name="kd">4.0</param>
      <param name="zero_torque_kd_min">0.005</param>
      <param name="zero_torque_kd_max">0.1</param>
      <command_interface name="position">
        <param name="min">-1.0472</param>
        <param name="max">1.5708</param>
      </command_interface>
      <command_interface name="velocity">
        <param name="min">-50.0</param>
        <param name="max">50.0</param>
      </command_interface>
      <command_interface name="effort">
        <param name="min">-6.0</param>
        <param name="max">6.0</param>
      </command_interface>
      <state_interface name="position"/>
      <state_interface name="velocity"/>
      <state_interface name="effort"/>
    </joint>

    <joint name="L5_joint">
      <param name="motor_id">5</param>
      <param name="motor_type">EL05</param>
      <param name="position_offset">0.0</param>
      <param name="direction">-1.0</param>
      <param name="kp">100.0</param>
      <param name="kd">4.0</param>
      <param name="zero_torque_kd_min">0.005</param>
      <param name="zero_torque_kd_max">0.05</param>
      <command_interface name="position">
        <param name="min">-1.5708</param>
        <param name="max">1.5708</param>
      </command_interface>
      <command_interface name="velocity">
        <param name="min">-50.0</param>
        <param name="max">50.0</param>
      </command_interface>
      <command_interface name="effort">
        <param name="min">-6.0</param>
        <param name="max">6.0</param>
      </command_interface>
      <state_interface name="position"/>
      <state_interface name="velocity"/>
      <state_interface name="effort"/>
    </joint>

    <joint name="L6_joint">
      <param name="motor_id">6</param>
      <param name="motor_type">EL05</param>
      <param name="position_offset">0.0</param>
      <param name="direction">1.0</param>
      <param name="kp">100.0</param>
      <param name="kd">4.0</param>
      <param name="zero_torque_kd_min">0.005</param>
      <param name="zero_torque_kd_max">0.05</param>
      <command_interface name="position">
        <param name="min">-1.5708</param>
        <param name="max">1.5708</param>
      </command_interface>
      <command_interface name="velocity">
        <param name="min">-50.0</param>
        <param name="max">50.0</param>
      </command_interface>
      <command_interface name="effort">
        <param name="min">-6.0</param>
        <param name="max">6.0</param>
      </command_interface>
      <state_interface name="position"/>
      <state_interface name="velocity"/>
      <state_interface name="effort"/>
    </joint>

    <joint name="L7_joint">
      <param name="motor_id">7</param>
      <param name="motor_type">EL05</param>
      <param name="position_offset">0.0</param>
      <param name="direction">1.0</param>
      <param name="zero_torque_kd_min">0.02</param>
      <param name="zero_torque_kd_max">0.10</param>
      <command_interface name="position">
        <param name="min">-1.5708</param>
        <param name="max">1.5708</param>
      </command_interface>
      <command_interface name="velocity">
        <param name="min">-50.0</param>
        <param name="max">50.0</param>
      </command_interface>
      <command_interface name="effort">
        <param name="min">-6.0</param>
        <param name="max">6.0</param>
      </command_interface>
      <state_interface name="position"/>
      <state_interface name="velocity"/>
      <state_interface name="effort"/>
    </joint>
  </ros2_control>
</robot>
