<?xml version="1.0" ?>
<!-- Generated using onshape-to-robot -->
<!-- Onshape https://cad.onshape.com/documents/2139d6249ad18a0629ecd155/w/a86523bcdb53c289a76cb994/e/2b2c47a834414785c43e5e23 -->
<robot name="EDULITE-A3">
  <!-- Link l1_urdf_urdf_asm_copy_1 -->
  <link name="l1_urdf_urdf_asm_copy_1">
    <inertial>
      <origin xyz="4.66057e-08 7.85527e-05 0.0336468" rpy="0 0 0"/>
      <mass value="0.498832"/>
      <inertia ixx="0.000371872" ixy="-1.33362e-08" ixz="5.96807e-10" iyy="0.000365137" iyz="-1.36721e-06" izz="0.000388475"/>
    </inertial>
    <!-- Part l1 -->
    <visual>
      <origin xyz="-0.000643355 -1.62314e-10 0.059" rpy="-2.21818e-14 -0 -1.94289e-16"/>
      <geometry>
        <mesh filename="package://meshes/l1.stl"/>
      </geometry>
      <material name="l1_material">
        <color rgba="0.301961 0.290196 0.262745 1"/>
      </material>
    </visual>
    <collision>
      <origin xyz="-0.000643355 -1.62314e-10 0.059" rpy="-2.21818e-14 -0 -1.94289e-16"/>
      <geometry>
        <mesh filename="package://meshes/l1.stl"/>
      </geometry>
    </collision>
  </link>
  <!-- Link l1_link_urdf_asm_copy_1 -->
  <link name="l1_link_urdf_asm_copy_1">
    <inertial>
      <origin xyz="-0.00232762 -0.00161986 0.0421389" rpy="0 0 0"/>
      <mass value="0.105244"/>
      <inertia ixx="0.000163151" ixy="-3.25924e-06" ixz="1.01303e-05" iyy="9.80821e-05" iyz="1.04567e-05" izz="0.000118753"/>
    </inertial>
    <!-- Part l2 -->
    <visual>
      <origin xyz="-0.000642857 0 0.001" rpy="3.14159 -0 1.30819e-41"/>
      <geometry>
        <mesh filename="package://meshes/l2.stl"/>
      </geometry>
      <material name="l2_material">
        <color rgba="0.972549 0.529412 0.00392157 1"/>
      </material>
    </visual>
    <collision>
      <origin xyz="-0.000642857 0 0.001" rpy="3.14159 -0 1.30819e-41"/>
      <geometry>
        <mesh filename="package://meshes/l2.stl"/>
      </geometry>
    </collision>
  </link>
  <!-- Link l2_l3_urdf_asm_copy_1 -->
  <link name="l2_l3_urdf_asm_copy_1">
    <inertial>
      <origin xyz="0.0949957 1.32911e-06 0.000626283" rpy="0 0 0"/>
      <mass value="0.836196"/>
      <inertia ixx="0.000419405" ixy="-4.27021e-07" ixz="-4.05336e-10" iyy="0.00708317" iyz="2.8291e-09" izz="0.00707892"/>
    </inertial>
    <!-- Part l3 -->
    <visual>
      <origin xyz="0.009 -0.07 -6.23721e-18" rpy="-1.5708 -2.78912e-28 3.72342e-28"/>
      <geometry>
        <mesh filename="package://meshes/l3.stl"/>
      </geometry>
      <material name="l3_material">
        <color rgba="0.301961 0.290196 0.262745 1"/>
      </material>
    </visual>
    <collision>
      <origin xyz="0.009 -0.07 -6.23721e-18" rpy="-1.5708 -2.78912e-28 3.72342e-28"/>
      <geometry>
        <mesh filename="package://meshes/l3.stl"/>
      </geometry>
    </collision>
  </link>
  <!-- Link l3_lnik_urdf_asm_copy_1 -->
  <link name="l3_lnik_urdf_asm_copy_1">
    <inertial>
      <origin xyz="-0.0743466 -0.0535452 -0.00326782" rpy="0 0 0"/>
      <mass value="0.262025"/>
      <inertia ixx="0.000333463" ixy="-0.000182996" ixz="-9.89508e-06" iyy="0.00130159" iyz="1.18614e-05" izz="0.00133147"/>
    </inertial>
    <!-- Part l4 -->
    <visual>
      <origin xyz="-0.181 -0.07 3.46945e-18" rpy="-1.5708 1.18102e-27 3.88578e-16"/>
      <geometry>
        <mesh filename="package://meshes/l4.stl"/>
      </geometry>
      <material name="l4_material">
        <color rgba="0.972549 0.529412 0.00392157 1"/>
      </material>
    </visual>
    <collision>
      <origin xyz="-0.181 -0.07 3.46945e-18" rpy="-1.5708 1.18102e-27 3.88578e-16"/>
      <geometry>
        <mesh filename="package://meshes/l4.stl"/>
      </geometry>
    </collision>
  </link>
  <!-- Link l4_l5_urdf_asm_copy_1 -->
  <link name="l4_l5_urdf_asm_copy_1">
    <inertial>
      <origin xyz="-0.0242818 -0.0298393 0.000368105" rpy="0 0 0"/>
      <mass value="0.55715"/>
      <inertia ixx="0.0006785" ixy="-0.000401622" ixz="-5.0507e-06" iyy="0.000503952" iyz="-6.21816e-06" izz="0.000993465"/>
    </inertial>
    <!-- Part l5 -->
    <visual>
      <origin xyz="0.004 0.134 4.85723e-17" rpy="1.5708 1.13007e-27 3.88578e-16"/>
      <geometry>
        <mesh filename="package://meshes/l5.stl"/>
      </geometry>
      <material name="l5_material">
        <color rgba="0.301961 0.290196 0.262745 1"/>
      </material>
    </visual>
    <collision>
      <origin xyz="0.004 0.134 4.85723e-17" rpy="1.5708 1.13007e-27 3.88578e-16"/>
      <geometry>
        <mesh filename="package://meshes/l5.stl"/>
      </geometry>
    </collision>
  </link>
  <!-- Link l6 -->
  <link name="l6">
    <inertial>
      <origin xyz="0.00527533 2.84815e-08 -0.0216678" rpy="0 0 0"/>
      <mass value="0.0392349"/>
      <inertia ixx="1.45554e-05" ixy="-2.84066e-12" ixz="4.08768e-06" iyy="1.4787e-05" iyz="-1.07753e-11" izz="6.36147e-06"/>
    </inertial>
    <!-- Part l6 -->
    <visual>
      <origin xyz="0.0532 -2.78535e-16 0.173" rpy="3.14159 -0 2.13192e-41"/>
      <geometry>
        <mesh filename="package://meshes/l6.stl"/>
      </geometry>
      <material name="l6_material">
        <color rgba="0.972549 0.529412 0.00392157 1"/>
      </material>
    </visual>
    <collision>
      <origin xyz="0.0532 -2.78535e-16 0.173" rpy="3.14159 -0 2.13192e-41"/>
      <geometry>
        <mesh filename="package://meshes/l6.stl"/>
      </geometry>
    </collision>
  </link>
  <!-- Link l5_l6_urdf_asm_copy_1 -->
  <link name="l5_l6_urdf_asm_copy_1">
    <inertial>
      <origin xyz="8.14367e-06 8.87434e-05 0.0699256" rpy="0 0 0"/>
      <mass value="0.657292"/>
      <inertia ixx="0.00132624" ixy="1.41465e-05" ixz="9.49712e-08" iyy="0.00177268" iyz="-7.87717e-06" izz="0.000610685"/>
    </inertial>
    <!-- Part el05_l6 -->
    <visual>
      <origin xyz="-4.10165e-17 -1.11022e-16 -0.0755" rpy="3.14159 1.65984e-16 2.60613e-16"/>
      <geometry>
        <mesh filename="package://meshes/el05_l6.stl"/>
      </geometry>
      <material name="el05_l6_material">
        <color rgba="0.301961 0.290196 0.262745 1"/>
      </material>
    </visual>
    <collision>
      <origin xyz="-4.10165e-17 -1.11022e-16 -0.0755" rpy="3.14159 1.65984e-16 2.60613e-16"/>
      <geometry>
        <mesh filename="package://meshes/el05_l6.stl"/>
      </geometry>
    </collision>
    <!-- Part jaw -->
    <visual>
      <origin xyz="-4.1053e-17 -1.11022e-16 -0.0755" rpy="3.14159 1.65984e-16 2.60613e-16"/>
      <geometry>
        <mesh filename="package://meshes/jaw.stl"/>
      </geometry>
      <material name="jaw_material">
        <color rgba="0.972549 0.529412 0.00392157 1"/>
      </material>
    </visual>
    <collision>
      <origin xyz="-4.1053e-17 -1.11022e-16 -0.0755" rpy="3.14159 1.65984e-16 2.60613e-16"/>
      <geometry>
        <mesh filename="package://meshes/jaw.stl"/>
      </geometry>
    </collision>
  </link>
  <!-- Joint from l6 to l5_l6_urdf_asm_copy_1 -->
  <joint name="L6_joint" type="revolute">
    <origin xyz="0.00685 -2.9256e-16 0.039" rpy="-1.5708 -0 -1.5708"/>
    <parent link="l6"/>
    <child link="l5_l6_urdf_asm_copy_1"/>
    <axis xyz="0 0 1"/>
    <limit effort="10" velocity="10" lower="-1.5708" upper="1.5708"/>
  </joint>
  <!-- Joint from l4_l5_urdf_asm_copy_1 to l6 -->
  <joint name="L5_joint" type="revolute">
    <origin xyz="-0.0492 -0.038 5.95508e-17" rpy="-1.5708 1.13007e-27 3.88578e-16"/>
    <parent link="l4_l5_urdf_asm_copy_1"/>
    <child link="l6"/>
    <axis xyz="0 0 1"/>
    <limit effort="10" velocity="10" lower="-1.5708" upper="1.5708"/>
  </joint>
  <!-- Joint from l3_lnik_urdf_asm_copy_1 to l4_l5_urdf_asm_copy_1 -->
  <joint name="L4_joint" type="revolute">
    <origin xyz="-0.185 0.064 6.93889e-18" rpy="-3.14159 1.18102e-27 3.88578e-16"/>
    <parent link="l3_lnik_urdf_asm_copy_1"/>
    <child link="l4_l5_urdf_asm_copy_1"/>
    <axis xyz="0 0 -1"/>
    <limit effort="10" velocity="10" lower="-1.0472" upper="1.5708"/>
  </joint>
  <!-- Joint from l2_l3_urdf_asm_copy_1 to l3_lnik_urdf_asm_copy_1 -->
  <joint name="L3_joint" type="revolute">
    <origin xyz="0.19 -2.77556e-17 -2.76776e-18" rpy="-9.46633e-29 -2.78912e-28 3.72342e-28"/>
    <parent link="l2_l3_urdf_asm_copy_1"/>
    <child link="l3_lnik_urdf_asm_copy_1"/>
    <axis xyz="0 0 1"/>
    <limit effort="10" velocity="10" lower="-4.01426" upper="-0"/>
  </joint>
  <!-- Joint from l1_link_urdf_asm_copy_1 to l2_l3_urdf_asm_copy_1 -->
  <joint name="L2_joint" type="revolute">
    <origin xyz="-0.00964286 3.46945e-18 -0.069" rpy="-1.5708 -0 1.30819e-41"/>
    <parent link="l1_link_urdf_asm_copy_1"/>
    <child link="l2_l3_urdf_asm_copy_1"/>
    <axis xyz="0 0 1"/>
    <limit effort="10" velocity="10" lower="-0" upper="3.66519"/>
  </joint>
  <!-- Joint from l1_urdf_urdf_asm_copy_1 to l1_link_urdf_asm_copy_1 -->
  <joint name="L1_joint" type="revolute">
    <origin xyz="-4.9779e-07 -1.62314e-10 0.06" rpy="3.14159 -5.8976e-28 2.77556e-17"/>
    <parent link="l1_urdf_urdf_asm_copy_1"/>
    <child link="l1_link_urdf_asm_copy_1"/>
    <axis xyz="0 0 -1"/>
    <limit effort="10" velocity="10" lower="-2.79253" upper="2.79253"/>
  </joint>
</robot>
